[2025-05-20T17:15:08.017+0000] {taskinstance.py:1159} INFO - Dependencies all met for dep_context=non-requeueable deps ti=<TaskInstance: flight_price_pipeline.load_csv manual__2025-05-20T17:15:04.374543+00:00 [queued]>
[2025-05-20T17:15:08.051+0000] {taskinstance.py:1159} INFO - Dependencies all met for dep_context=requeueable deps ti=<TaskInstance: flight_price_pipeline.load_csv manual__2025-05-20T17:15:04.374543+00:00 [queued]>
[2025-05-20T17:15:08.052+0000] {taskinstance.py:1361} INFO - Starting attempt 1 of 1
[2025-05-20T17:15:08.096+0000] {taskinstance.py:1382} INFO - Executing <Task(PythonOperator): load_csv> on 2025-05-20 17:15:04.374543+00:00
[2025-05-20T17:15:08.105+0000] {standard_task_runner.py:57} INFO - Started process 232 to run task
[2025-05-20T17:15:08.112+0000] {standard_task_runner.py:84} INFO - Running: ['***', 'tasks', 'run', 'flight_price_pipeline', 'load_csv', 'manual__2025-05-20T17:15:04.374543+00:00', '--job-id', '16', '--raw', '--subdir', 'DAGS_FOLDER/dag_flight_pipeline.py', '--cfg-path', '/tmp/tmphtiqs_50']
[2025-05-20T17:15:08.121+0000] {standard_task_runner.py:85} INFO - Job 16: Subtask load_csv
[2025-05-20T17:15:08.253+0000] {task_command.py:416} INFO - Running <TaskInstance: flight_price_pipeline.load_csv manual__2025-05-20T17:15:04.374543+00:00 [running]> on host 1b6ed7c8df07
[2025-05-20T17:15:08.453+0000] {taskinstance.py:1662} INFO - Exporting env vars: AIRFLOW_CTX_DAG_OWNER='***' AIRFLOW_CTX_DAG_ID='flight_price_pipeline' AIRFLOW_CTX_TASK_ID='load_csv' AIRFLOW_CTX_EXECUTION_DATE='2025-05-20T17:15:04.374543+00:00' AIRFLOW_CTX_TRY_NUMBER='1' AIRFLOW_CTX_DAG_RUN_ID='manual__2025-05-20T17:15:04.374543+00:00'
[2025-05-20T17:15:08.458+0000] {load.py:6} INFO - Starting CSV load task
[2025-05-20T17:15:09.564+0000] {load.py:12} INFO - Loaded 57000 rows from CSV
[2025-05-20T17:15:09.895+0000] {load.py:53} ERROR - Error loading CSV to MySQL: 'Base Fare'
Traceback (most recent call last):
  File "/home/airflow/.local/lib/python3.8/site-packages/pandas/core/indexes/base.py", line 3653, in get_loc
    return self._engine.get_loc(casted_key)
  File "pandas/_libs/index.pyx", line 147, in pandas._libs.index.IndexEngine.get_loc
  File "pandas/_libs/index.pyx", line 176, in pandas._libs.index.IndexEngine.get_loc
  File "pandas/_libs/hashtable_class_helper.pxi", line 7080, in pandas._libs.hashtable.PyObjectHashTable.get_item
  File "pandas/_libs/hashtable_class_helper.pxi", line 7088, in pandas._libs.hashtable.PyObjectHashTable.get_item
KeyError: 'Base Fare'

The above exception was the direct cause of the following exception:

Traceback (most recent call last):
  File "/opt/airflow/dags/tasks/load.py", line 39, in load_csv_to_mysql
    row['Base Fare'],
  File "/home/airflow/.local/lib/python3.8/site-packages/pandas/core/series.py", line 1007, in __getitem__
    return self._get_value(key)
  File "/home/airflow/.local/lib/python3.8/site-packages/pandas/core/series.py", line 1116, in _get_value
    loc = self.index.get_loc(label)
  File "/home/airflow/.local/lib/python3.8/site-packages/pandas/core/indexes/base.py", line 3655, in get_loc
    raise KeyError(key) from err
KeyError: 'Base Fare'
[2025-05-20T17:15:09.919+0000] {taskinstance.py:1937} ERROR - Task failed with exception
Traceback (most recent call last):
  File "/home/airflow/.local/lib/python3.8/site-packages/pandas/core/indexes/base.py", line 3653, in get_loc
    return self._engine.get_loc(casted_key)
  File "pandas/_libs/index.pyx", line 147, in pandas._libs.index.IndexEngine.get_loc
  File "pandas/_libs/index.pyx", line 176, in pandas._libs.index.IndexEngine.get_loc
  File "pandas/_libs/hashtable_class_helper.pxi", line 7080, in pandas._libs.hashtable.PyObjectHashTable.get_item
  File "pandas/_libs/hashtable_class_helper.pxi", line 7088, in pandas._libs.hashtable.PyObjectHashTable.get_item
KeyError: 'Base Fare'

The above exception was the direct cause of the following exception:

Traceback (most recent call last):
  File "/home/airflow/.local/lib/python3.8/site-packages/airflow/operators/python.py", line 192, in execute
    return_value = self.execute_callable()
  File "/home/airflow/.local/lib/python3.8/site-packages/airflow/operators/python.py", line 209, in execute_callable
    return self.python_callable(*self.op_args, **self.op_kwargs)
  File "/opt/airflow/dags/tasks/load.py", line 39, in load_csv_to_mysql
    row['Base Fare'],
  File "/home/airflow/.local/lib/python3.8/site-packages/pandas/core/series.py", line 1007, in __getitem__
    return self._get_value(key)
  File "/home/airflow/.local/lib/python3.8/site-packages/pandas/core/series.py", line 1116, in _get_value
    loc = self.index.get_loc(label)
  File "/home/airflow/.local/lib/python3.8/site-packages/pandas/core/indexes/base.py", line 3655, in get_loc
    raise KeyError(key) from err
KeyError: 'Base Fare'
[2025-05-20T17:15:09.941+0000] {taskinstance.py:1400} INFO - Marking task as FAILED. dag_id=flight_price_pipeline, task_id=load_csv, execution_date=20250520T171504, start_date=20250520T171508, end_date=20250520T171509
[2025-05-20T17:15:09.976+0000] {standard_task_runner.py:104} ERROR - Failed to execute job 16 for task load_csv ('Base Fare'; 232)
[2025-05-20T17:15:10.019+0000] {local_task_job_runner.py:228} INFO - Task exited with return code 1
[2025-05-20T17:15:10.081+0000] {taskinstance.py:2778} INFO - 0 downstream tasks scheduled from follow-on schedule check
