[2025-05-20T02:07:36.158+0000] {taskinstance.py:1159} INFO - Dependencies all met for dep_context=non-requeueable deps ti=<TaskInstance: flight_price_pipeline.load_csv manual__2025-05-20T02:07:32.336204+00:00 [queued]>
[2025-05-20T02:07:36.178+0000] {taskinstance.py:1159} INFO - Dependencies all met for dep_context=requeueable deps ti=<TaskInstance: flight_price_pipeline.load_csv manual__2025-05-20T02:07:32.336204+00:00 [queued]>
[2025-05-20T02:07:36.179+0000] {taskinstance.py:1361} INFO - Starting attempt 1 of 1
[2025-05-20T02:07:36.221+0000] {taskinstance.py:1382} INFO - Executing <Task(PythonOperator): load_csv> on 2025-05-20 02:07:32.336204+00:00
[2025-05-20T02:07:36.231+0000] {standard_task_runner.py:57} INFO - Started process 240 to run task
[2025-05-20T02:07:36.239+0000] {standard_task_runner.py:84} INFO - Running: ['***', 'tasks', 'run', 'flight_price_pipeline', 'load_csv', 'manual__2025-05-20T02:07:32.336204+00:00', '--job-id', '3', '--raw', '--subdir', 'DAGS_FOLDER/dag_flight_pipeline.py', '--cfg-path', '/tmp/tmp0tsc2saq']
[2025-05-20T02:07:36.246+0000] {standard_task_runner.py:85} INFO - Job 3: Subtask load_csv
[2025-05-20T02:07:36.354+0000] {task_command.py:416} INFO - Running <TaskInstance: flight_price_pipeline.load_csv manual__2025-05-20T02:07:32.336204+00:00 [running]> on host 1965b2b307d4
[2025-05-20T02:07:36.547+0000] {taskinstance.py:1662} INFO - Exporting env vars: AIRFLOW_CTX_DAG_OWNER='***' AIRFLOW_CTX_DAG_ID='flight_price_pipeline' AIRFLOW_CTX_TASK_ID='load_csv' AIRFLOW_CTX_EXECUTION_DATE='2025-05-20T02:07:32.336204+00:00' AIRFLOW_CTX_TRY_NUMBER='1' AIRFLOW_CTX_DAG_RUN_ID='manual__2025-05-20T02:07:32.336204+00:00'
[2025-05-20T02:07:36.550+0000] {load.py:6} INFO - Starting CSV load task
[2025-05-20T02:07:36.556+0000] {load.py:42} ERROR - Error loading CSV to MySQL: [Errno 2] No such file or directory: '/opt/***/Flight_Price_Dataset_of_Bangladesh.csv'
[2025-05-20T02:07:36.557+0000] {taskinstance.py:1937} ERROR - Task failed with exception
Traceback (most recent call last):
  File "/opt/airflow/dags/tasks/load.py", line 9, in load_csv_to_mysql
    df = pd.read_csv('/opt/airflow/Flight_Price_Dataset_of_Bangladesh.csv')
  File "/home/airflow/.local/lib/python3.8/site-packages/pandas/io/parsers/readers.py", line 912, in read_csv
    return _read(filepath_or_buffer, kwds)
  File "/home/airflow/.local/lib/python3.8/site-packages/pandas/io/parsers/readers.py", line 577, in _read
    parser = TextFileReader(filepath_or_buffer, **kwds)
  File "/home/airflow/.local/lib/python3.8/site-packages/pandas/io/parsers/readers.py", line 1407, in __init__
    self._engine = self._make_engine(f, self.engine)
  File "/home/airflow/.local/lib/python3.8/site-packages/pandas/io/parsers/readers.py", line 1661, in _make_engine
    self.handles = get_handle(
  File "/home/airflow/.local/lib/python3.8/site-packages/pandas/io/common.py", line 859, in get_handle
    handle = open(
FileNotFoundError: [Errno 2] No such file or directory: '/opt/airflow/Flight_Price_Dataset_of_Bangladesh.csv'

During handling of the above exception, another exception occurred:

Traceback (most recent call last):
  File "/home/airflow/.local/lib/python3.8/site-packages/airflow/operators/python.py", line 192, in execute
    return_value = self.execute_callable()
  File "/home/airflow/.local/lib/python3.8/site-packages/airflow/operators/python.py", line 209, in execute_callable
    return self.python_callable(*self.op_args, **self.op_kwargs)
  File "/opt/airflow/dags/tasks/load.py", line 45, in load_csv_to_mysql
    cursor.close()
UnboundLocalError: local variable 'cursor' referenced before assignment
[2025-05-20T02:07:36.590+0000] {taskinstance.py:1400} INFO - Marking task as FAILED. dag_id=flight_price_pipeline, task_id=load_csv, execution_date=20250520T020732, start_date=20250520T020736, end_date=20250520T020736
[2025-05-20T02:07:36.620+0000] {standard_task_runner.py:104} ERROR - Failed to execute job 3 for task load_csv (local variable 'cursor' referenced before assignment; 240)
[2025-05-20T02:07:36.653+0000] {local_task_job_runner.py:228} INFO - Task exited with return code 1
[2025-05-20T02:07:36.702+0000] {taskinstance.py:2778} INFO - 0 downstream tasks scheduled from follow-on schedule check
